# MongoDB Index Creation Fix

## Summary of the Issue

The bot was encountering this error during initialization:

```
The field 'unique' is not valid for an _id index specification. Specification: { unique: true, name: "_id_1", key: { _id: 1 }, v: 2 }
```

## Cause

The error occurred because we were trying to create a unique index on the `_id` field in MongoDB collections. In MongoDB, the `_id` field is already indexed and unique by default, so specifying the `unique: true` option for this field is redundant and causes an error.

## Fixes Implemented

1. **Removed Unnecessary Index Creation**:
   - Removed attempts to create unique indexes on `_id` fields
   - Added comments explaining that `_id` is indexed by default

2. **Added Error Handling**:
   - Added try-except blocks around index creation operations
   - This allows the bot to continue functioning even if index creation fails

3. **Added Connection Validation**:
   - Created a `validate_connection()` method to check MongoDB connectivity
   - Added this verification step before attempting to create indexes

4. **Added MongoDB URI Format Verification**:
   - Added validation for the MongoDB URI format in `start.py`
   - Ensures the URI starts with either "mongodb://" or "mongodb+srv://"

5. **Enhanced Error Reporting**:
   - Added more descriptive error messages
   - Added specific exit codes for different types of errors

## Testing the Fix

To test the fix, deploy the changes and monitor the logs to ensure:

1. The bot successfully connects to MongoDB
2. No more errors about invalid index specifications
3. Collections and other (non-_id) indexes are created properly

## Future Considerations

1. Consider adding a migration function to ensure smooth upgrades
2. Consider adding more robust MongoDB health checks
3. Add database backup functionality before making changes
